Workbook
Name NativeTimeline_Encounter_Date: #N/A
Name Slicer_Age_Group: #N/A
Name Slicer_Alcohol_Use: #N/A
Name Slicer_Chronic_Condition: #N/A
Name Slicer_Sex: #N/A
Name Slicer_Smoking_Status: #N/A

Sheet Clean_Dataset
A1: Patient_ID | B1: Encounter_ID | C1: Encounter_Date | D1: Encounter_Type | E1: Facility | F1: County | G1: Provider | H1: Patient_DOB | I1: Age_at_Encounter | J1: Age Group | K1: Sex | L1: Ethnicity | M1: Insurance_Status | N1: Smoking_Status | O1: Alcohol_Use | P1: Primary_ICD11_Code | Q1: Disease Category | R1: Primary_Diagnosis | S1: Chronic_Condition | T1: Current_Medications | U1: Num_Medications | V1: LOINC Code | W1: Test Category | X1: Test Name | Y1: Test Results | Z1: HBA1C Category | AA1: BP_Systolic_mmHg | AB1: BP_Diastolic_mmHg | AC1: BP Control | AD1: Blood Pressure Reading (mmHg) | AE1: HR_bpm | AF1: RR_breaths_per_min | AG1: Temp_C | AH1: BMI_kg_m2 | AI1: BMI_Category | AJ1: SpO2_pct | AK1: LOINC_BP_Sys | AL1: LOINC_BP_Dia | AM1: LOINC_HR | AN1: LOINC_BMI | AO1: LOINC_SpO2
A2: PID-0001 | B2: ENC-0001-01 | C2: 44959 | D2: Inpatient | E2: Central District Hospital | F2: Kisumu | G2: Dr. T. Osei | H2: 38330 | I2: 21 | J2: {=_xlfn.IFS(EHR[[#This Row],[Age_at_Encounter]]<18,"Adolescent",AND(EHR[[#This Row],[Age_at_Encounter]]>=18,EHR[[#This Row],[Age_at_Encounter]]<=34),"Young Adults",AND(EHR[[#This Row],[Age_at_Encounter]]>=35,EHR[[#This Row],[Age_at_Encounter]]<=49),"Middle Age",AND(EHR[[#This Row],[Age_at_Encounter]]>=50,EHR[[#This Row],[Age_at_Encounter]]<=64),"Late middle Age",EHR[[#This Row],[Age_at_Encounter]]>=65,"Senior Adults")} -> Young Adults | K2: Male | L2: South Asian | M2: National Insurance | N2: Never | O2: None | P2: 3A00 | Q2: =_xlfn.XLOOKUP(EHR[[#This Row],[Primary_ICD11_Code]],'03_ICD11_Reference'!A:A,'03_ICD11_Reference'!D:D,,0) -> Haematological | R2: Iron deficiency anaemia | S2: No | T2: Metoprolol 50mg BD; Clopidogrel 75mg OD | U2: 2 | V2: =_xlfn.XLOOKUP(EHR[[#This Row],[Encounter_ID]],'02_Lab_Results'!B:B,'02_Lab_Results'!D:D,,0) -> 2085-9 | W2: =_xlfn.XLOOKUP(EHR[[#This Row],[LOINC Code]],'04_LOINC_Reference'!A:A,'04_LOINC_Reference'!F:F,,0) -> Biochemistry | X2: =_xlfn.XLOOKUP(EHR[[#This Row],[LOINC Code]],'02_Lab_Results'!D:D,'02_Lab_Results'!E:E,,0) -> HDL cholesterol | Y2: =_xlfn.XLOOKUP(EHR[[#This Row],[LOINC Code]],'02_Lab_Results'!D:D,'02_Lab_Results'!J:J,,0) -> Normal | Z2: {=_xlfn.XLOOKUP(1,(B2=B$2:B$500)*(V$2:V$500="4548-4"),Y$2:Y$500,"Not Tested")} -> Not Tested | AA2: 98 | AB2: 68 | AC2: =IF(AND(EHR[[#This Row],[BP_Systolic_mmHg]]<140,EHR[[#This Row],[BP_Diastolic_mmHg]]<90),"Controlled",IF(OR(EHR[[#This Row],[BP_Systolic_mmHg]]="Not Recorded",EHR[[#This Row],[BP_Diastolic_mmHg]]="Not Recorded"),"No Reading","Uncontrolled")) -> Controlled | AD2: =_xlfn.CONCAT(EHR[[#This Row],[BP_Systolic_mmHg]],"/",EHR[[#This Row],[BP_Diastolic_mmHg]]) -> 98/68 | AE2: 88 | AF2: 12 | AG2: 36.6 | AH2: 36 | AI2: =IF(EHR[[#This Row],[BMI_kg_m2]]>=30,"Obese","Non-Obese") -> Obese | AJ2: 94 | AK2: 8480-6 | AL2: 8462-4 | AM2: 8867-4 | AN2: 39156-5 | AO2: 59408-5
A3: PID-0002 | B3: ENC-0002-01 | C3: 45279 | D3: Outpatient | E3: Eastside Clinic | F3: Eldoret | G3: Dr. S. Okonkwo | H3: 32258 | I3: 37 | J3: {=_xlfn.IFS(EHR[[#This Row],[Age_at_Encounter]]<18,"Adolescent",AND(EHR[[#This Row],[Age_at_Encounter]]>=18,EHR[[#This Row],[Age_at_Encounter]]<=34),"Young Adults",AND(EHR[[#This Row],[Age_at_Encounter]]>=35,EHR[[#This Row],[Age_at_Encounter]]<=49),"Middle Age",AND(EHR[[#This Row],[Age_at_Encounter]]>=50,EHR[[#This Row],[Age_at_Encounter]]<=64),"Late middle Age",EHR[[#This Row],[Age_at_Encounter]]>=65,"Senior Adults")} -> Middle Age | K3: Female | L3: Middle Eastern | M3: None | N3: Unknown | O3: None | P3: 5A10 | Q3: =_xlfn.XLOOKUP(EHR[[#This Row],[Primary_ICD11_Code]],'03_ICD11_Reference'!A:A,'03_ICD11_Reference'!D:D,,0) -> Endocrine | R3: Type 1 diabetes mellitus | S3: Yes | T3: Clopidogrel 75mg OD; Warfarin (variable); Metformin 1g BD | U3: 3 | V3: =_xlfn.XLOOKUP(EHR[[#This Row],[Encounter_ID]],'02_Lab_Results'!B:B,'02_Lab_Results'!D:D,,0) -> 718-7 | W3: =_xlfn.XLOOKUP(EHR[[#This Row],[LOINC Code]],'04_LOINC_Reference'!A:A,'04_LOINC_Reference'!F:F,,0) -> Biochemistry | X3: =_xlfn.XLOOKUP(EHR[[#This Row],[LOINC Code]],'02_Lab_Results'!D:D,'02_Lab_Results'!E:E,,0) -> Haemoglobin | Y3: =_xlfn.XLOOKUP(EHR[[#This Row],[LOINC Code]],'02_Lab_Results'!D:D,'02_Lab_Results'!J:J,,0) -> Normal | Z3: {=_xlfn.XLOOKUP(1,(B3=B$2:B$500)*(V$2:V$500="4548-4"),Y$2:Y$500,"Not Tested")} -> Not Tested | AA3: 149 | AB3: 103 | AC3: =IF(AND(EHR[[#This Row],[BP_Systolic_mmHg]]<140,EHR[[#This Row],[BP_Diastolic_mmHg]]<90),"Controlled",IF(OR(EHR[[#This Row],[BP_Systolic_mmHg]]="Not Recorded",EHR[[#This Row],[BP_Diastolic_mmHg]]="Not Recorded"),"No Reading","Uncontrolled")) -> Uncontrolled | AD3: =_xlfn.CONCAT(EHR[[#This Row],[BP_Systolic_mmHg]],"/",EHR[[#This Row],[BP_Diastolic_mmHg]]) -> 149/103 | AE3: 105 | AF3: 21 | AG3: 39.1 | AH3: 28.3 | AI3: =IF(EHR[[#This Row],[BMI_kg_m2]]>=30,"Obese","Non-Obese") -> Non-Obese | AJ3: 94 | AK3: 8480-6 | AL3: 8462-4 | AM3: 8867-4 | AN3: 39156-5 | AO3: 59408-5
A4: PID-0003 | B4: ENC-0003-01 | C4: 45613 | D4: Outpatient | E4: Eastside Clinic | F4: Nairobi | G4: Dr. F. Hassan | H4: 34889 | I4: 30 | J4: {=_xlfn.IFS(EHR[[#This Row],[Age_at_Encounter]]<18,"Adolescent",AND(EHR[[#This Row],[Age_at_Encounter]]>=18,EHR[[#This Row],[Age_at_Encounter]]<=34),"Young Adults",AND(EHR[[#This Row],[Age_at_Encounter]]>=35,EHR[[#This Row],[Age_at_Encounter]]<=49),"Middle Age",AND(EHR[[#This Row],[Age_at_Encounter]]>=50,EHR[[#This Row],[Age_at_Encounter]]<=64),"Late middle Age",EHR[[#This Row],[Age_at_Encounter]]>=65,"Senior Adults")} -> Young Adults | K4: Male | L4: East Asian | M4: Private | N4: Ex-smoker | O4: Regular | P4: LA90 | Q4: =_xlfn.XLOOKUP(EHR[[#This Row],[Primary_ICD11_Code]],'03_ICD11_Reference'!A:A,'03_ICD11_Reference'!D:D,,0) -> Renal | R4: Chronic kidney disease stage 3 | S4: Yes | T4: Bisoprolol 5mg OD; Prednisolone 5mg OD; Aspirin 75mg OD; Levothyroxine 50mcg OD | U4: 4 | V4: =_xlfn.XLOOKUP(EHR[[#This Row],[Encounter_ID]],'02_Lab_Results'!B:B,'02_Lab_Results'!D:D,,0) -> 2160-0 | W4: =_xlfn.XLOOKUP(EHR[[#This Row],[LOINC Code]],'04_LOINC_Reference'!A:A,'04_LOINC_Reference'!F:F,,0) -> Biochemistry | X4: =_xlfn.XLOOKUP(EHR[[#This Row],[LOINC Code]],'02_Lab_Results'!D:D,'02_Lab_Results'!E:E,,0) -> Serum creatinine | Y4: =_xlfn.XLOOKUP(EHR[[#This Row],[LOINC Code]],'02_Lab_Results'!D:D,'02_Lab_Results'!J:J,,0) -> Normal | Z4: {=_xlfn.XLOOKUP(1,(B4=B$2:B$500)*(V$2:V$500="4548-4"),Y$2:Y$500,"Not Tested")} -> Not Tested | AA4: 119 | AB4: 111 | AC4: =IF(AND(EHR[[#This Row],[BP_Systolic_mmHg]]<140,EHR[[#This Row],[BP_Diastolic_mmHg]]<90),"Controlled",IF(OR(EHR[[#This Row],[BP_Systolic_mmHg]]="Not Recorded",EHR[[#This Row],[BP_Diastolic_mmHg]]="Not Recorded"),"No Reading","Uncontrolled")) -> Uncontrolled | AD4: =_xlfn.CONCAT(EHR[[#This Row],[BP_Systolic_mmHg]],"/",EHR[[#This Row],[BP_Diastolic_mmHg]]) -> 119/111 | AE4: 99 | AF4: 22 | AG4: 36.5 | AH4: 38.3 | AI4: =IF(EHR[[#This Row],[BMI_kg_m2]]>=30,"Obese","Non-Obese") -> Obese | AJ4: 89 | AK4: 8480-6 | AL4: 8462-4 | AM4: 8867-4 | AN4: 39156-5 | AO4: 59408-5
A5: PID-0003 | B5: ENC-0003-02 | C5: 45201 | D5: Follow-up | E5: Riverside Specialist Centre | F5: Eldoret | G5: Dr. T. Osei | H5: 34889 | I5: 30 | J5: {=_xlfn.IFS(EHR[[#This Row],[Age_at_Encounter]]<18,"Adolescent",AND(EHR[[#This Row],[Age_at_Encounter]]>=18,EHR[[#This Row],[Age_at_Encounter]]<=34),"Young Adults",AND(EHR[[#This Row],[Age_at_Encounter]]>=35,EHR[[#This Row],[Age_at_Encounter]]<=49),"Middle Age",AND(EHR[[#This Row],[Age_at_Encounter]]>=50,EHR[[#This Row],[Age_at_Encounter]]<=64),"Late middle Age",EHR[[#This Row],[Age_at_Encounter]]>=65,"Senior Adults")} -> Young Adults | K5: Male | L5: Mixed/Other | M5: Private | N5: Ex-smoker | O5: Regular | P5: LA90 | Q5: =_xlfn.XLOOKUP(EHR[[#This Row],[Primary_ICD11_Code]],'03_ICD11_Reference'!A:A,'03_ICD11_Reference'!D:D,,0) -> Renal | R5: Chronic kidney disease stage 3 | S5: Yes | T5: Salbutamol 100mcg PRN; Bisoprolol 5mg OD; None; Aspirin 75mg OD | U5: 4 | V5: =_xlfn.XLOOKUP(EHR[[#This Row],[Encounter_ID]],'02_Lab_Results'!B:B,'02_Lab_Results'!D:D,,0) -> 2345-7 | W5: =_xlfn.XLOOKUP(EHR[[#This Row],[LOINC Code]],'04_LOINC_Reference'!A:A,'04_LOINC_Reference'!F:F,,0) -> Biochemistry | X5: =_xlfn.XLOOKUP(EHR[[#This Row],[LOINC Code]],'02_Lab_Results'!D:D,'02_Lab_Results'!E:E,,0) -> Serum glucose (fasting) | Y5: =_xlfn.XLOOKUP(EHR[[#This Row],[LOINC Code]],'02_Lab_Results'!D:D,'02_Lab_Results'!J:J,,0) -> Normal | Z5: {=_xlfn.XLOOKUP(1,(B5=B$2:B$500)*(V$2:V$500="4548-4"),Y$2:Y$500,"Not Tested")} -> Not Tested | AA5: 101 | AB5: 110 | AC5: =IF(AND(EHR[[#This Row],[BP_Systolic_mmHg]]<140,EHR[[#This Row],[BP_Diastolic_mmHg]]<90),"Controlled",IF(OR(EHR[[#This Row],[BP_Systolic_mmHg]]="Not Recorded",EHR[[#This Row],[BP_Diastolic_mmHg]]="Not Recorded"),"No Reading","Uncontrolled")) -> Uncontrolled | AD5: =_xlfn.CONCAT(EHR[[#This Row],[BP_Systolic_mmHg]],"/",EHR[[#This Row],[BP_Diastolic_mmHg]]) -> 101/110 | AE5: 93 | AF5: 23 | AG5: 36.7 | AH5: 31.7 | AI5: =IF(EHR[[#This Row],[BMI_kg_m2]]>=30,"Obese","Non-Obese") -> Obese | AJ5: 99 | AK5: 8480-6 | AL5: 8462-4 | AM5: 8867-4 | AN5: 39156-5 | AO5: 59408-5
A6: PID-0003 | B6: ENC-0003-03 | C6: 45335 | D6: Telehealth | E6: Community Health Centre | F6: Kitale | G6: NP J. Nakamura | H6: 34889 | I6: 30 | J6: {=_xlfn.IFS(EHR[[#This Row],[Age_at_Encounter]]<18,"Adolescent",AND(EHR[[#This Row],[Age_at_Encounter]]>=18,EHR[[#This Row],[Age_at_Encounter]]<=34),"Young Adults",AND(EHR[[#This Row],[Age_at_Encounter]]>=35,EHR[[#This Row],[Age_at_Encounter]]<=49),"Middle Age",AND(EHR[[#This Row],[Age_at_Encounter]]>=50,EHR[[#This Row],[Age_at_Encounter]]<=64),"Late middle Age",EHR[[#This Row],[Age_at_Encounter]]>=65,"Senior Adults")} -> Young Adults | K6: Male | L6: Mixed/Other | M6: Private | N6: Ex-smoker | O6: Regular | P6: LA90 | Q6: =_xlfn.XLOOKUP(EHR[[#This Row],[Primary_ICD11_Code]],'03_ICD11_Reference'!A:A,'03_ICD11_Reference'!D:D,,0) -> Renal | R6: Chronic kidney disease stage 3 | S6: Yes | T6: Ramipril 5mg OD; Metformin 1g BD | U6: 2 | V6: =_xlfn.XLOOKUP(EHR[[#This Row],[Encounter_ID]],'02_Lab_Results'!B:B,'02_Lab_Results'!D:D,,0) -> 2093-3 | W6: =_xlfn.XLOOKUP(EHR[[#This Row],[LOINC Code]],'04_LOINC_Reference'!A:A,'04_LOINC_Reference'!F:F,,0) -> Biochemistry | X6: =_xlfn.XLOOKUP(EHR[[#This Row],[LOINC Code]],'02_Lab_Results'!D:D,'02_Lab_Results'!E:E,,0) -> Total cholesterol | Y6: =_xlfn.XLOOKUP(EHR[[#This Row],[LOINC Code]],'02_Lab_Results'!D:D,'02_Lab_Results'!J:J,,0) -> Normal | Z6: {=_xlfn.XLOOKUP(1,(B6=B$2:B$500)*(V$2:V$500="4548-4"),Y$2:Y$500,"Not Tested")} -> Not Tested | AA6: 128 | AB6: 115 | AC6: =IF(AND(EHR[[#This Row],[BP_Systolic_mmHg]]<140,EHR[[#This Row],[BP_Diastolic_mmHg]]<90),"Controlled",IF(OR(EHR[[#This Row],[BP_Systolic_mmHg]]="Not Recorded",EHR[[#This Row],[BP_Diastolic_mmHg]]="Not Recorded"),"No Reading","Uncontrolled")) -> Uncontrolled | AD6: =_xlfn.CONCAT(EHR[[#This Row],[BP_Systolic_mmHg]],"/",EHR[[#This Row],[BP_Diastolic_mmHg]]) -> 128/115 | AE6: 60 | AF6: 20 | AG6: 38.4 | AH6: 42 | AI6: =IF(EHR[[#This Row],[BMI_kg_m2]]>=30,"Obese","Non-Obese") -> Obese | AJ6: 89 | AK6: 8480-6 | AL6: 8462-4 | AM6: 8867-4 | AN6: 39156-5 | AO6: 59408-5 | AR6: Total Patients
A7: PID-0003 | B7: ENC-0003-04 | C7: 45184 | D7: Emergency | E7: Community Health Centre | F7: Nairobi | G7: Dr. Y. Kim | H7: 34889 | I7: 30 | J7: {=_xlfn.IFS(EHR[[#This Row],[Age_at_Encounter]]<18,"Adolescent",AND(EHR[[#This Row],[Age_at_Encounter]]>=18,EHR[[#This Row],[Age_at_Encounter]]<=34),"Young Adults",AND(EHR[[#This Row],[Age_at_Encounter]]>=35,EHR[[#This Row],[Age_at_Encounter]]<=49),"Middle Age",AND(EHR[[#This Row],[Age_at_Encounter]]>=50,EHR[[#This Row],[Age_at_Encounter]]<=64),"Late middle Age",EHR[[#This Row],[Age_at_Encounter]]>=65,"Senior Adults")} -> Young Adults | K7: Male | L7: Mixed/Other | M7: Private | N7: Ex-smoker | O7: Regular | P7: LA90 | Q7: =_xlfn.XLOOKUP(EHR[[#This Row],[Primary_ICD11_Code]],'03_ICD11_Reference'!A:A,'03_ICD11_Reference'!D:D,,0) -> Renal | R7: Chronic kidney disease stage 3 | S7: Yes | T7: Atorvastatin 40mg ON; Omeprazole 20mg OD; Ramipril 5mg OD | U7: 3 | V7: =_xlfn.XLOOKUP(EHR[[#This Row],[Encounter_ID]],'02_Lab_Results'!B:B,'02_Lab_Results'!D:D,,0) -> 2777-1 | W7: =_xlfn.XLOOKUP(EHR[[#This Row],[LOINC Code]],'04_LOINC_Reference'!A:A,'04_LOINC_Reference'!F:F,,0) -> Biochemistry | X7: =_xlfn.XLOOKUP(EHR[[#This Row],[LOINC Code]],'02_Lab_Results'!D:D,'02_Lab_Results'!E:E,,0) -> Serum phosphate | Y7: =_xlfn.XLOOKUP(EHR[[#This Row],[LOINC Code]],'02_Lab_Results'!D:D,'02_Lab_Results'!J:J,,0) -> Normal | Z7: {=_xlfn.XLOOKUP(1,(B7=B$2:B$500)*(V$2:V$500="4548-4"),Y$2:Y$500,"Not Tested")} -> Not Tested | AA7: 182 | AB7: 107 | AC7: =IF(AND(EHR[[#This Row],[BP_Systolic_mmHg]]<140,EHR[[#This Row],[BP_Diastolic_mmHg]]<90),"Controlled",IF(OR(EHR[[#This Row],[BP_Systolic_mmHg]]="Not Recorded",EHR[[#This Row],[BP_Diastolic_mmHg]]="Not Recorded"),"No Reading","Uncontrolled")) -> Uncontrolled | AD7: =_xlfn.CONCAT(EHR[[#This Row],[BP_Systolic_mmHg]],"/",EHR[[#This Row],[BP_Diastolic_mmHg]]) -> 182/107 | AE7: 51 | AF7: 24 | AG7: 38.2 | AH7: 32.8 | AI7: =IF(EHR[[#This Row],[BMI_kg_m2]]>=30,"Obese","Non-Obese") -> Obese | AJ7: 90 | AK7: 8480-6 | AL7: 8462-4 | AM7: 8867-4 | AN7: 39156-5 | AO7: 59408-5 | AR7: {=SUMPRODUCT(1/COUNTIF(EHR[Patient_ID],EHR[Patient_ID]))} -> 120
A8: PID-0003 | B8: ENC-0003-05 | C8: 45707 | D8: Outpatient | E8: Riverside Specialist Centre | F8: Thika | G8: NP J. Nakamura | H8: 34889 | I8: 30 | J8: {=_xlfn.IFS(EHR[[#This Row],[Age_at_Encounter]]<18,"Adolescent",AND(EHR[[#This Row],[Age_at_Encounter]]>=18,EHR[[#This Row],[Age_at_Encounter]]<=34),"Young Adults",AND(EHR[[#This Row],[Age_at_Encounter]]>=35,EHR[[#This Row],[Age_at_Encounter]]<=49),"Middle Age",AND(EHR[[#This Row],[Age_at_Encounter]]>=50,EHR[[#This Row],[Age_at_Encounter]]<=64),"Late middle Age",EHR[[#This Row],[Age_at_Encounter]]>=65,"Senior Adults")} -> Young Adults | K8: Male | L8: Black African | M8: Private | N8: Ex-smoker | O8: Regular | P8: LA90 | Q8: =_xlfn.XLOOKUP(EHR[[#This Row],[Primary_ICD11_Code]],'03_ICD11_Reference'!A:A,'03_ICD11_Reference'!D:D,,0) -> Renal | R8: Chronic kidney disease stage 3 | S8: Yes | T8: Prednisolone 5mg OD; Empagliflozin 10mg OD | U8: 2 | V8: =_xlfn.XLOOKUP(EHR[[#This Row],[Encounter_ID]],'02_Lab_Results'!B:B,'02_Lab_Results'!D:D,,0) -> 2823-3 | W8: =_xlfn.XLOOKUP(EHR[[#This Row],[LOINC Code]],'04_LOINC_Reference'!A:A,'04_LOINC_Reference'!F:F,,0) -> Biochemistry | X8: =_xlfn.XLOOKUP(EHR[[#This Row],[LOINC Code]],'02_Lab_Results'!D:D,'02_Lab_Results'!E:E,,0) -> Serum potassium | Y8: =_xlfn.XLOOKUP(EHR[[#This Row],[LOINC Code]],'02_Lab_Results'!D:D,'02_Lab_Results'!J:J,,0) -> Normal | Z8: {=_xlfn.XLOOKUP(1,(B8=B$2:B$500)*(V$2:V$500="4548-4"),Y$2:Y$500,"Not Tested")} -> Not Tested | AA8: 111 | AB8: 110 | AC8: =IF(AND(EHR[[#This Row],[BP_Systolic_mmHg]]<140,EHR[[#This Row],[BP_Diastolic_mmHg]]<90),"Controlled",IF(OR(EHR[[#This Row],[BP_Systolic_mmHg]]="Not Recorded",EHR[[#This Row],[BP_Diastolic_mmHg]]="Not Recorded"),"No Reading","Uncontrolled")) -> Uncontrolled | AD8: =_xlfn.CONCAT(EHR[[#This Row],[BP_Systolic_mmHg]],"/",EHR[[#This Row],[BP_Diastolic_mmHg]]) -> 111/110 | AE8: 115 | AF8: 17 | AG8: 38 | AH8: 34.9 | AI8: =IF(EHR[[#This Row],[BMI_kg_m2]]>=30,"Obese","Non-Obese") -> Obese | AJ8: 89 | AK8: 8480-6 | AL8: 8462-4 | AM8: 8867-4 | AN8: 39156-5 | AO8: 59408-5 | AR8: Most common diagnosis
A9: PID-0003 | B9: ENC-0003-06 | C9: 45041 | D9: Outpatient | E9: Riverside Specialist Centre | F9: Kisumu | G9: Dr. L. Patel | H9: 34889 | I9: 30 | J9: {=_xlfn.IFS(EHR[[#This Row],[Age_at_Encounter]]<18,"Adolescent",AND(EHR[[#This Row],[Age_at_Encounter]]>=18,EHR[[#This Row],[Age_at_Encounter]]<=34),"Young Adults",AND(EHR[[#This Row],[Age_at_Encounter]]>=35,EHR[[#This Row],[Age_at_Encounter]]<=49),"Middle Age",AND(EHR[[#This Row],[Age_at_Encounter]]>=50,EHR[[#This Row],[Age_at_Encounter]]<=64),"Late middle Age",EHR[[#This Row],[Age_at_Encounter]]>=65,"Senior Adults")} -> Young Adults | K9: Male | L9: Hispanic/Latino | M9: Private | N9: Ex-smoker | O9: Regular | P9: LA90 | Q9: =_xlfn.XLOOKUP(EHR[[#This Row],[Primary_ICD11_Code]],'03_ICD11_Reference'!A:A,'03_ICD11_Reference'!D:D,,0) -> Renal | R9: Chronic kidney disease stage 3 | S9: Yes | T9: Dapagliflozin 10mg OD | U9: 1 | V9: =_xlfn.XLOOKUP(EHR[[#This Row],[Encounter_ID]],'02_Lab_Results'!B:B,'02_Lab_Results'!D:D,,0) -> 2823-3 | W9: =_xlfn.XLOOKUP(EHR[[#This Row],[LOINC Code]],'04_LOINC_Reference'!A:A,'04_LOINC_Reference'!F:F,,0) -> Biochemistry | X9: =_xlfn.XLOOKUP(EHR[[#This Row],[LOINC Code]],'02_Lab_Results'!D:D,'02_Lab_Results'!E:E,,0) -> Serum potassium | Y9: =_xlfn.XLOOKUP(EHR[[#This Row],[LOINC Code]],'02_Lab_Results'!D:D,'02_Lab_Results'!J:J,,0) -> Normal | Z9: {=_xlfn.XLOOKUP(1,(B9=B$2:B$500)*(V$2:V$500="4548-4"),Y$2:Y$500,"Not Tested")} -> Not Tested | AA9: 179 | AB9: 108 | AC9: =IF(AND(EHR[[#This Row],[BP_Systolic_mmHg]]<140,EHR[[#This Row],[BP_Diastolic_mmHg]]<90),"Controlled",IF(OR(EHR[[#This Row],[BP_Systolic_mmHg]]="Not Recorded",EHR[[#This Row],[BP_Diastolic_mmHg]]="Not Recorded"),"No Reading","Uncontrolled")) -> Uncontrolled | AD9: =_xlfn.CONCAT(EHR[[#This Row],[BP_Systolic_mmHg]],"/",EHR[[#This Row],[BP_Diastolic_mmHg]]) -> 179/108 | AE9: 112 | AF9: 17 | AG9: 36.2 | AH9: 42.5 | AI9: =IF(EHR[[#This Row],[BMI_kg_m2]]>=30,"Obese","Non-Obese") -> Obese | AJ9: 99 | AK9: 8480-6 | AL9: 8462-4 | AM9: 8867-4 | AN9: 39156-5 | AO9: 59408-5 | AR9: {=INDEX(EHR[Primary_Diagnosis],MATCH(MAX(COUNTIF(EHR[Primary_Diagnosis],EHR[Primary_Diagnosis])),COUNTIF(EHR[Primary_Diagnosis],EHR[Primary_Diagnosis]),0))} -> Metabolic syndrome
A10: PID-0004 | B10: ENC-0004-01 | C10: 45592 | D10: Outpatient | E10: Eastside Clinic | F10: Mombasa | G10: Dr. A. Mwangi | H10: 31549 | I10: 39 | J10: {=_xlfn.IFS(EHR[[#This Row],[Age_at_Encounter]]<18,"Adolescent",AND(EHR[[#This Row],[Age_at_Encounter]]>=18,EHR[[#This Row],[Age_at_Encounter]]<=34),"Young Adults",AND(EHR[[#This Row],[Age_at_Encounter]]>=35,EHR[[#This Row],[Age_at_Encounter]]<=49),"Middle Age",AND(EHR[[#This Row],[Age_at_Encounter]]>=50,EHR[[#This Row],[Age_at_Encounter]]<=64),"Late middle Age",EHR[[#This Row],[Age_at_Encounter]]>=65,"Senior Adults")} -> Middle Age | K10: Female | L10: Middle Eastern | M10: National Insurance | N10: Current | O10: Unknown | P10: 8A25 | Q10: =_xlfn.XLOOKUP(EHR[[#This Row],[Primary_ICD11_Code]],'03_ICD11_Reference'!A:A,'03_ICD11_Reference'!D:D,,0) -> Neurological | R10: Epilepsy | S10: Yes | T10: Amlodipine 5mg OD; Metformin 1g BD | U10: 2 | V10: =_xlfn.XLOOKUP(EHR[[#This Row],[Encounter_ID]],'02_Lab_Results'!B:B,'02_Lab_Results'!D:D,,0) -> 6768-6 | W10: =_xlfn.XLOOKUP(EHR[[#This Row],[LOINC Code]],'04_LOINC_Reference'!A:A,'04_LOINC_Reference'!F:F,,0) -> Biochemistry | X10: =_xlfn.XLOOKUP(EHR[[#This Row],[LOINC Code]],'02_Lab_Results'!D:D,'02_Lab_Results'!E:E,,0) -> ALP | Y10: =_xlfn.XLOOKUP(EHR[[#This Row],[LOINC Code]],'02_Lab_Results'!D:D,'02_Lab_Results'!J:J,,0) -> High | Z10: {=_xlfn.XLOOKUP(1,(B10=B$2:B$500)*(V$2:V$500="4548-4"),Y$2:Y$500,"Not Tested")} -> Not Tested | AA10: 129 | AB10: 109 | AC10: =IF(AND(EHR[[#This Row],[BP_Systolic_mmHg]]<140,EHR[[#This Row],[BP_Diastolic_mmHg]]<90),"Controlled",IF(OR(EHR[[#This Row],[BP_Systolic_mmHg]]="Not Recorded",EHR[[#This Row],[BP_Diastolic_mmHg]]="Not Recorded"),"No Reading","Uncontrolled")) -> Uncontrolled | AD10: =_xlfn.CONCAT(EHR[[#This Row],[BP_Systolic_mmHg]],"/",EHR[[#This Row],[BP_Diastolic_mmHg]]) -> 129/109 | AE10: 84 | AF10: 16 | AG10: 36.2 | AH10: 18.1 | AI10: =IF(EHR[[#This Row],[BMI_kg_m2]]>=30,"Obese","Non-Obese") -> Non-Obese | AJ10: 94 | AK10: 8480-6 | AL10: 8462-4 | AM10: 8867-4 | AN10: 39156-5 | AO10: 59408-5 | AR10: Total Encounters
A11: PID-0004 | B11: ENC-0004-02 | C11: 45265 | D11: Outpatient | E11: Central District Hospital | F11: Malindi | G11: Dr. F. Hassan | H11: 31549 | I11: 39 | J11: {=_xlfn.IFS(EHR[[#This Row],[Age_at_Encounter]]<18,"Adolescent",AND(EHR[[#This Row],[Age_at_Encounter]]>=18,EHR[[#This Row],[Age_at_Encounter]]<=34),"Young Adults",AND(EHR[[#This Row],[Age_at_Encounter]]>=35,EHR[[#This Row],[Age_at_Encounter]]<=49),"Middle Age",AND(EHR[[#This Row],[Age_at_Encounter]]>=50,EHR[[#This Row],[Age_at_Encounter]]<=64),"Late middle Age",EHR[[#This Row],[Age_at_Encounter]]>=65,"Senior Adults")} -> Middle Age | K11: Female | L11: East Asian | M11: National Insurance | N11: Current | O11: Unknown | P11: 8A25 | Q11: =_xlfn.XLOOKUP(EHR[[#This Row],[Primary_ICD11_Code]],'03_ICD11_Reference'!A:A,'03_ICD11_Reference'!D:D,,0) -> Neurological | R11: Epilepsy | S11: Yes | T11: Aspirin 75mg OD; Dapagliflozin 10mg OD; Ramipril 5mg OD; Warfarin (variable) | U11: 4 | V11: =_xlfn.XLOOKUP(EHR[[#This Row],[Encounter_ID]],'02_Lab_Results'!B:B,'02_Lab_Results'!D:D,,0) -> 789-8 | W11: =_xlfn.XLOOKUP(EHR[[#This Row],[LOINC Code]],'04_LOINC_Reference'!A:A,'04_LOINC_Reference'!F:F,,0) -> Biochemistry | X11: =_xlfn.XLOOKUP(EHR[[#This Row],[LOINC Code]],'02_Lab_Results'!D:D,'02_Lab_Results'!E:E,,0) -> RBC count | Y11: =_xlfn.XLOOKUP(EHR[[#This Row],[LOINC Code]],'02_Lab_Results'!D:D,'02_Lab_Results'!J:J,,0) -> High | Z11: {=_xlfn.XLOOKUP(1,(B11=B$2:B$500)*(V$2:V$500="4548-4"),Y$2:Y$500,"Not Tested")} -> Not Tested | AA11: 101 | AB11: 69 | AC11: =IF(AND(EHR[[#This Row],[BP_Systolic_mmHg]]<140,EHR[[#This Row],[BP_Diastolic_mmHg]]<90),"Controlled",IF(OR(EHR[[#This Row],[BP_Systolic_mmHg]]="Not Recorded",EHR[[#This Row],[BP_Diastolic_mmHg]]="Not Recorded"),"No Reading","Uncontrolled")) -> Controlled | AD11: =_xlfn.CONCAT(EHR[[#This Row],[BP_Systolic_mmHg]],"/",EHR[[#This Row],[BP_Diastolic_mmHg]]) -> 101/69 | AE11: 100 | AF11: 15 | AG11: 36.4 | AH11: 44.2 | AI11: =IF(EHR[[#This Row],[BMI_kg_m2]]>=30,"Obese","Non-Obese") -> Obese | AJ11: 94 | AK11: 8480-6 | AL11: 8462-4 | AM11: 8867-4 | AN11: 39156-5 | AO11: 59408-5 | AR11: =COUNTA(EHR[Encounter_ID]) -> 398
A12: PID-0005 | B12: ENC-0005-01 | C12: 45121 | D12: Follow-up | E12: Central District Hospital | F12: Mombasa | G12: Dr. R. Mendes | H12: 17869 | I12: 77 | J12: {=_xlfn.IFS(EHR[[#This Row],[Age_at_Encounter]]<18,"Adolescent",AND(EHR[[#This Row],[Age_at_Encounter]]>=18,EHR[[#This Row],[Age_at_Encounter]]<=34),"Young Adults",AND(EHR[[#This Row],[Age_at_Encounter]]>=35,EHR[[#This Row],[Age_at_Encounter]]<=49),"Middle Age",AND(EHR[[#This Row],[Age_at_Encounter]]>=50,EHR[[#This Row],[Age_at_Encounter]]<=64),"Late middle Age",EHR[[#This Row],[Age_at_Encounter]]>=65,"Senior Adults")} -> Senior Adults | K12: Female | L12: White European | M12: Employer | N12: Current | O12: None | P12: BA41 | Q12: =_xlfn.XLOOKUP(EHR[[#This Row],[Primary_ICD11_Code]],'03_ICD11_Reference'!A:A,'03_ICD11_Reference'!D:D,,0) -> Cardiovascular | R12: Acute MI – STEMI | S12: No | T12: Lisinopril 10mg OD | U12: 1 | V12: =_xlfn.XLOOKUP(EHR[[#This Row],[Encounter_ID]],'02_Lab_Results'!B:B,'02_Lab_Results'!D:D,,0) -> 17861-6 | W12: =_xlfn.XLOOKUP(EHR[[#This Row],[LOINC Code]],'04_LOINC_Reference'!A:A,'04_LOINC_Reference'!F:F,,0) -> Biochemistry | X12: =_xlfn.XLOOKUP(EHR[[#This Row],[LOINC Code]],'02_Lab_Results'!D:D,'02_Lab_Results'!E:E,,0) -> Serum calcium | Y12: =_xlfn.XLOOKUP(EHR[[#This Row],[LOINC Code]],'02_Lab_Results'!D:D,'02_Lab_Results'!J:J,,0) -> High | Z12: {=_xlfn.XLOOKUP(1,(B12=B$2:B$500)*(V$2:V$500="4548-4"),Y$2:Y$500,"Not Tested")} -> Not Tested | AA12: 143 | AB12: 63 | AC12: =IF(AND(EHR[[#This Row],[BP_Systolic_mmHg]]<140,EHR[[#This Row],[BP_Diastolic_mmHg]]<90),"Controlled",IF(OR(EHR[[#This Row],[BP_Systolic_mmHg]]="Not Recorded",EHR[[#This Row],[BP_Diastolic_mmHg]]="Not Recorded"),"No Reading","Uncontrolled")) -> Uncontrolled | AD12: =_xlfn.CONCAT(EHR[[#This Row],[BP_Systolic_mmHg]],"/",EHR[[#This Row],[BP_Diastolic_mmHg]]) -> 143/63 | AE12: 64 | AF12: 19 | AG12: 38.8 | AH12: 19.6 | AI12: =IF(EHR[[#This Row],[BMI_kg_m2]]>=30,"Obese","Non-Obese") -> Non-Obese | AJ12: 98 | AK12: 8480-6 | AL12: 8462-4 | AM12: 8867-4 | AN12: 39156-5 | AO12: 59408-5 | AR12: Average BMI
A13: PID-0006 | B13: ENC-0006-01 | C13: 45198 | D13: Outpatient | E13: Riverside Specialist Centre | F13: Garissa | G13: Dr. A. Mwangi | H13: 16656 | I13: 80 | J13: {=_xlfn.IFS(EHR[[#This Row],[Age_at_Encounter]]<18,"Adolescent",AND(EHR[[#This Row],[Age_at_Encounter]]>=18,EHR[[#This Row],[Age_at_Encounter]]<=34),"Young Adults",AND(EHR[[#This Row],[Age_at_Encounter]]>=35,EHR[[#This Row],[Age_at_Encounter]]<=49),"Middle Age",AND(EHR[[#This Row],[Age_at_Encounter]]>=50,EHR[[#This Row],[Age_at_Encounter]]<=64),"Late middle Age",EHR[[#This Row],[Age_at_Encounter]]>=65,"Senior Adults")} -> Senior Adults | K13: Female | L13: Hispanic/Latino | M13: National Insurance | N13: Unknown | O13: None | P13: FA24 | Q13: =_xlfn.XLOOKUP(EHR[[#This Row],[Primary_ICD11_Code]],'03_ICD11_Reference'!A:A,'03_ICD11_Reference'!D:D,,0) -> Gastroenterology | R13: Gastro-oesophageal reflux disease | S13: Yes | T13: Salbutamol 100mcg PRN; Warfarin (variable); Omeprazole 20mg OD; Clopidogrel 75mg OD | U13: 4 | V13: =_xlfn.XLOOKUP(EHR[[#This Row],[Encounter_ID]],'02_Lab_Results'!B:B,'02_Lab_Results'!D:D,,0) -> 2345-7 | W13: =_xlfn.XLOOKUP(EHR[[#This Row],[LOINC Code]],'04_LOINC_Reference'!A:A,'04_LOINC_Reference'!F:F,,0) -> Biochemistry | X13: =_xlfn.XLOOKUP(EHR[[#This Row],[LOINC Code]],'02_Lab_Results'!D:D,'02_Lab_Results'!E:E,,0) -> Serum glucose (fasting) | Y13: =_xlfn.XLOOKUP(EHR[[#This Row],[LOINC Code]],'02_Lab_Results'!D:D,'02_Lab_Results'!J:J,,0) -> Normal | Z13: {=_xlfn.XLOOKUP(1,(B13=B$2:B$500)*(V$2:V$500="4548-4"),Y$2:Y$500,"Not Tested")} -> Not Tested | AA13: 178 | AB13: 102 | AC13: =IF(AND(EHR[[#This Row],[BP_Systolic_mmHg]]<140,EHR[[#This Row],[BP_Diastolic_mmHg]]<90),"Controlled",IF(OR(EHR[[#This Row],[BP_Systolic_mmHg]]="Not Recorded",EHR[[#This Row],[BP_Diastolic_mmHg]]="Not Recorded"),"No Reading","Uncontrolled")) -> Uncontrolled | AD13: =_xlfn.CONCAT(EHR[[#This Row],[BP_Systolic_mmHg]],"/",EHR[[#This Row],[BP_Diastolic_mmHg]]) -> 178/102 | AE13: 71 | AF13: 23 | AG13: 38.3 | AH13: 39.8 | AI13: =IF(EHR[[#This Row],[BMI_kg_m2]]>=30,"Obese","Non-Obese") -> Obese | AJ13: 96 | AK13: 8480-6 | AL13: 8462-4 | AM13: 8867-4 | AN13: 39156-5 | AO13: 59408-5 | AR13: =AVERAGEIF(EHR[BMI_kg_m2],">"&0,EHR[BMI_kg_m2]) -> 31.557106
A14: PID-0007 | B14: ENC-0007-01 | C14: 44997 | D14: Follow-up | E14: Riverside Specialist Centre | F14: Garissa | G14: Dr. F. Hassan | H14: 36544 | I14: 25 | J14: {=_xlfn.IFS(EHR[[#This Row],[Age_at_Encounter]]<18,"Adolescent",AND(EHR[[#This Row],[Age_at_Encounter]]>=18,EHR[[#This Row],[Age_at_Encounter]]<=34),"Young Adults",AND(EHR[[#This Row],[Age_at_Encounter]]>=35,EHR[[#This Row],[Age_at_Encounter]]<=49),"Middle Age",AND(EHR[[#This Row],[Age_at_Encounter]]>=50,EHR[[#This Row],[Age_at_Encounter]]<=64),"Late middle Age",EHR[[#This Row],[Age_at_Encounter]]>=65,"Senior Adults")} -> Young Adults | K14: Female | L14: South Asian | M14: National Insurance | N14: Never | O14: None | P14: BA80,5A11 | Q14: =_xlfn.XLOOKUP(EHR[[#This Row],[Primary_ICD11_Code]],'03_ICD11_Reference'!A:A,'03_ICD11_Reference'!D:D,,0) -> Multi-system | R14: Hypertension + T2DM | S14: Yes | T14: Ramipril 5mg OD | U14: 1 | V14: =_xlfn.XLOOKUP(EHR[[#This Row],[Encounter_ID]],'02_Lab_Results'!B:B,'02_Lab_Results'!D:D,,0) -> 17861-6 | W14: =_xlfn.XLOOKUP(EHR[[#This Row],[LOINC Code]],'04_LOINC_Reference'!A:A,'04_LOINC_Reference'!F:F,,0) -> Biochemistry | X14: =_xlfn.XLOOKUP(EHR[[#This Row],[LOINC Code]],'02_Lab_Results'!D:D,'02_Lab_Results'!E:E,,0) -> Serum calcium | Y14: =_xlfn.XLOOKUP(EHR[[#This Row],[LOINC Code]],'02_Lab_Results'!D:D,'02_Lab_Results'!J:J,,0) -> High | Z14: {=_xlfn.XLOOKUP(1,(B14=B$2:B$500)*(V$2:V$500="4548-4"),Y$2:Y$500,"Not Tested")} -> Not Tested | AA14: 149 | AB14: 96 | AC14: =IF(AND(EHR[[#This Row],[BP_Systolic_mmHg]]<140,EHR[[#This Row],[BP_Diastolic_mmHg]]<90),"Controlled",IF(OR(EHR[[#This Row],[BP_Systolic_mmHg]]="Not Recorded",EHR[[#This Row],[BP_Diastolic_mmHg]]="Not Recorded"),"No Reading","Uncontrolled")) -> Uncontrolled | AD14: =_xlfn.CONCAT(EHR[[#This Row],[BP_Systolic_mmHg]],"/",EHR[[#This Row],[BP_Diastolic_mmHg]]) -> 149/96 | AE14: 68 | AF14: 14 | AG14: 38.8 | AH14: 24.5 | AI14: =IF(EHR[[#This Row],[BMI_kg_m2]]>=30,"Obese","Non-Obese") -> Non-Obese | AJ14: 95 | AK14: 8480-6 | AL14: 8462-4 | AM14: 8867-4 | AN14: 39156-5 | AO14: 59408-5
A15: PID-0007 | B15: ENC-0007-02 | C15: 45136 | D15: Telehealth | E15: Riverside Specialist Centre | F15: Kitale | G15: Dr. S. Okonkwo | H15: 36544 | I15: 25 | J15: {=_xlfn.IFS(EHR[[#This Row],[Age_at_Encounter]]<18,"Adolescent",AND(EHR[[#This Row],[Age_at_Encounter]]>=18,EHR[[#This Row],[Age_at_Encounter]]<=34),"Young Adults",AND(EHR[[#This Row],[Age_at_Encounter]]>=35,EHR[[#This Row],[Age_at_Encounter]]<=49),"Middle Age",AND(EHR[[#This Row],[Age_at_Encounter]]>=50,EHR[[#This Row],[Age_at_Encounter]]<=64),"Late middle Age",EHR[[#This Row],[Age_at_Encounter]]>=65,"Senior Adults")} -> Young Adults | K15: Female | L15: Black African | M15: National Insurance | N15: Never | O15: None | P15: BA80,5A11 | Q15: =_xlfn.XLOOKUP(EHR[[#This Row],[Primary_ICD11_Code]],'03_ICD11_Reference'!A:A,'03_ICD11_Reference'!D:D,,0) -> Multi-system | R15: Hypertension + T2DM | S15: Yes | T15: Amlodipine 5mg OD | U15: 1 | V15: =_xlfn.XLOOKUP(EHR[[#This Row],[Encounter_ID]],'02_Lab_Results'!B:B,'02_Lab_Results'!D:D,,0) -> 6690-2 | W15: =_xlfn.XLOOKUP(EHR[[#This Row],[LOINC Code]],'04_LOINC_Reference'!A:A,'04_LOINC_Reference'!F:F,,0) -> Biochemistry | X15: =_xlfn.XLOOKUP(EHR[[#This Row],[LOINC Code]],'02_Lab_Results'!D:D,'02_Lab_Results'!E:E,,0) -> WBC count | Y15: =_xlfn.XLOOKUP(EHR[[#This Row],[LOINC Code]],'02_Lab_Results'!D:D,'02_Lab_Results'!J:J,,0) -> Low | Z15: {=_xlfn.XLOOKUP(1,(B15=B$2:B$500)*(V$2:V$500="4548-4"),Y$2:Y$500,"Not Tested")} -> Not Tested | AA15: 155 | AB15: 74 | AC15: =IF(AND(EHR[[#This Row],[BP_Systolic_mmHg]]<140,EHR[[#This Row],[BP_Diastolic_mmHg]]<90),"Controlled",IF(OR(EHR[[#This Row],[BP_Systolic_mmHg]]="Not Recorded",EHR[[#This Row],[BP_Diastolic_mmHg]]="Not Recorded"),"No Reading","Uncontrolled")) -> Uncontrolled | AD15: =_xlfn.CONCAT(EHR[[#This Row],[BP_Systolic_mmHg]],"/",EHR[[#This Row],[BP_Diastolic_mmHg]]) -> 155/74 | AE15: 70 | AF15: 14 | AG15: 38.1 | AH15: 30.5 | AI15: =IF(EHR[[#This Row],[BMI_kg_m2]]>=30,"Obese","Non-Obese") -> Obese | AJ15: 99 | AK15: 8480-6 | AL15: 8462-4 | AM15: 8867-4 | AN15: 39156-5 | AO15: 59408-5
A16: PID-0007 | B16: ENC-0007-03 | C16: 45477 | D16: Follow-up | E16: Metro Emergency Unit | F16: Mombasa | G16: Dr. L. Patel | H16: 36544 | I16: 25 | J16: {=_xlfn.IFS(EHR[[#This Row],[Age_at_Encounter]]<18,"Adolescent",AND(EHR[[#This Row],[Age_at_Encounter]]>=18,EHR[[#This Row],[Age_at_Encounter]]<=34),"Young Adults",AND(EHR[[#This Row],[Age_at_Encounter]]>=35,EHR[[#This Row],[Age_at_Encounter]]<=49),"Middle Age",AND(EHR[[#This Row],[Age_at_Encounter]]>=50,EHR[[#This Row],[Age_at_Encounter]]<=64),"Late middle Age",EHR[[#This Row],[Age_at_Encounter]]>=65,"Senior Adults")} -> Young Adults | K16: Female | L16: South Asian | M16: National Insurance | N16: Never | O16: None | P16: BA80,5A11 | Q16: =_xlfn.XLOOKUP(EHR[[#This Row],[Primary_ICD11_Code]],'03_ICD11_Reference'!A:A,'03_ICD11_Reference'!D:D,,0) -> Multi-system | R16: Hypertension + T2DM | S16: Yes | T16: None; Empagliflozin 10mg OD; Amlodipine 5mg OD | U16: 3 | V16: =_xlfn.XLOOKUP(EHR[[#This Row],[Encounter_ID]],'02_Lab_Results'!B:B,'02_Lab_Results'!D:D,,0) -> 2093-3 | W16: =_xlfn.XLOOKUP(EHR[[#This Row],[LOINC Code]],'04_LOINC_Reference'!A:A,'04_LOINC_Reference'!F:F,,0) -> Biochemistry | X16: =_xlfn.XLOOKUP(EHR[[#This Row],[LOINC Code]],'02_Lab_Results'!D:D,'02_Lab_Results'!E:E,,0) -> Total cholesterol | Y16: =_xlfn.XLOOKUP(EHR[[#This Row],[LOINC Code]],'02_Lab_Results'!D:D,'02_Lab_Results'!J:J,,0) -> Normal | Z16: {=_xlfn.XLOOKUP(1,(B16=B$2:B$500)*(V$2:V$500="4548-4"),Y$2:Y$500,"Not Tested")} -> Not Tested | AA16: 114 | AB16: 71 | AC16: =IF(AND(EHR[[#This Row],[BP_Systolic_mmHg]]<140,EHR[[#This Row],[BP_Diastolic_mmHg]]<90),"Controlled",IF(OR(EHR[[#This Row],[BP_Systolic_mmHg]]="Not Recorded",EHR[[#This Row],[BP_Diastolic_mmHg]]="Not Recorded"),"No Reading","Uncontrolled")) -> Controlled | AD16: =_xlfn.CONCAT(EHR[[#This Row],[BP_Systolic_mmHg]],"/",EHR[[#This Row],[BP_Diastolic_mmHg]]) -> 114/71 | AE16: 120 | AF16: 26 | AG16: 38.8 | AH16: 28 | AI16: =IF(EHR[[#This Row],[BMI_kg_m2]]>=30,"Obese","Non-Obese") -> Non-Obese | AJ16: 89 | AK16: 8480-6 | AL16: 8462-4 | AM16: 8867-4 | AN16: 39156-5 | AO16: 59408-5
A17: PID-0007 | B17: ENC-0007-04 | C17: 45045 | D17: Outpatient | E17: Central District Hospital | F17: Malindi | G17: Dr. Y. Kim | H17: 36544 | I17: 25 | J17: {=_xlfn.IFS(EHR[[#This Row],[Age_at_Encounter]]<18,"Adolescent",AND(EHR[[#This Row],[Age_at_Encounter]]>=18,EHR[[#This Row],[Age_at_Encounter]]<=34),"Young Adults",AND(EHR[[#This Row],[Age_at_Encounter]]>=35,EHR[[#This Row],[Age_at_Encounter]]<=49),"Middle Age",AND(EHR[[#This Row],[Age_at_Encounter]]>=50,EHR[[#This Row],[Age_at_Encounter]]<=64),"Late middle Age",EHR[[#This Row],[Age_at_Encounter]]>=65,"Senior Adults")} -> Young Adults | K17: Female | L17: Black African | M17: National Insurance | N17: Never | O17: None | P17: BA80,5A11 | Q17: =_xlfn.XLOOKUP(EHR[[#This Row],[Primary_ICD11_Code]],'03_ICD11_Reference'!A:A,'03_ICD11_Reference'!D:D,,0) -> Multi-system | R17: Hypertension + T2DM | S17: Yes | T17: Empagliflozin 10mg OD; Dapagliflozin 10mg OD; Bisoprolol 5mg OD | U17: 3 | V17: =_xlfn.XLOOKUP(EHR[[#This Row],[Encounter_ID]],'02_Lab_Results'!B:B,'02_Lab_Results'!D:D,,0) -> 13457-7 | W17: =_xlfn.XLOOKUP(EHR[[#This Row],[LOINC Code]],'04_LOINC_Reference'!A:A,'04_LOINC_Reference'!F:F,,0) -> Biochemistry | X17: =_xlfn.XLOOKUP(EHR[[#This Row],[LOINC Code]],'02_Lab_Results'!D:D,'02_Lab_Results'!E:E,,0) -> LDL cholesterol | Y17: =_xlfn.XLOOKUP(EHR[[#This Row],[LOINC Code]],'02_Lab_Results'!D:D,'02_Lab_Results'!J:J,,0) -> High | Z17: {=_xlfn.XLOOKUP(1,(B17=B$2:B$500)*(V$2:V$500="4548-4"),Y$2:Y$500,"Not Tested")} -> Not Tested | AA17: 175 | AB17: 100 | AC17: =IF(AND(EHR[[#This Row],[BP_Systolic_mmHg]]<140,EHR[[#This Row],[BP_Diastolic_mmHg]]<90),"Controlled",IF(OR(EHR[[#This Row],[BP_Systolic_mmHg]]="Not Recorded",EHR[[#This Row],[BP_Diastolic_mmHg]]="Not Recorded"),"No Reading","Uncontrolled")) -> Uncontrolled | AD17: =_xlfn.CONCAT(EHR[[#This Row],[BP_Systolic_mmHg]],"/",EHR[[#This Row],[BP_Diastolic_mmHg]]) -> 175/100 | AE17: 62 | AF17: 17 | AG17: 36.7 | AH17: 27.3 | AI17: =IF(EHR[[#This Row],[BMI_kg_m2]]>=30,"Obese","Non-Obese") -> Non-Obese | AJ17: 96 | AK17: 8480-6 | AL17: 8462-4 | AM17: 8867-4 | AN17: 39156-5 | AO17: 59408-5
A18: PID-0007 | B18: ENC-0007-05 | C18: 44930 | D18: Emergency | E18: Riverside Specialist Centre | F18: Nairobi | G18: Dr. F. Hassan | H18: 36544 | I18: 25 | J18: {=_xlfn.IFS(EHR[[#This Row],[Age_at_Encounter]]<18,"Adolescent",AND(EHR[[#This Row],[Age_at_Encounter]]>=18,EHR[[#This Row],[Age_at_Encounter]]<=34),"Young Adults",AND(EHR[[#This Row],[Age_at_Encounter]]>=35,EHR[[#This Row],[Age_at_Encounter]]<=49),"Middle Age",AND(EHR[[#This Row],[Age_at_Encounter]]>=50,EHR[[#This Row],[Age_at_Encounter]]<=64),"Late middle Age",EHR[[#This Row],[Age_at_Encounter]]>=65,"Senior Adults")} -> Young Adults | K18: Female | L18: Mixed/Other | M18: National Insurance | N18: Never | O18: None | P18: BA80,5A11 | Q18: =_xlfn.XLOOKUP(EHR[[#This Row],[Primary_ICD11_Code]],'03_ICD11_Reference'!A:A,'03_ICD11_Reference'!D:D,,0) -> Multi-system | R18: Hypertension + T2DM | S18: Yes | T18: Metformin 1g BD | U18: 1 | V18: =_xlfn.XLOOKUP(EHR[[#This Row],[Encounter_ID]],'02_Lab_Results'!B:B,'02_Lab_Results'!D:D,,0) -> 789-8 | W18: =_xlfn.XLOOKUP(EHR[[#This Row],[LOINC Code]],'04_LOINC_Reference'!A:A,'04_LOINC_Reference'!F:F,,0) -> Biochemistry | X18: =_xlfn.XLOOKUP(EHR[[#This Row],[LOINC Code]],'02_Lab_Results'!D:D,'02_Lab_Results'!E:E,,0) -> RBC count | Y18: =_xlfn.XLOOKUP(EHR[[#This Row],[LOINC Code]],'02_Lab_Results'!D:D,'02_Lab_Results'!J:J,,0) -> High | Z18: {=_xlfn.XLOOKUP(1,(B18=B$2:B$500)*(V$2:V$500="4548-4"),Y$2:Y$500,"Not Tested")} -> Not Tested | AA18: 125 | AB18: 63 | AC18: =IF(AND(EHR[[#This Row],[BP_Systolic_mmHg]]<140,EHR[[#This Row],[BP_Diastolic_mmHg]]<90),"Controlled",IF(OR(EHR[[#This Row],[BP_Systolic_mmHg]]="Not Recorded",EHR[[#This Row],[BP_Diastolic_mmHg]]="Not Recorded"),"No Reading","Uncontrolled")) -> Controlled | AD18: =_xlfn.CONCAT(EHR[[#This Row],[BP_Systolic_mmHg]],"/",EHR[[#This Row],[BP_Diastolic_mmHg]]) -> 125/63 | AE18: 123 | AF18: 15 | AG18: 37.4 | AH18: 37.6 | AI18: =IF(EHR[[#This Row],[BMI_kg_m2]]>=30,"Obese","Non-Obese") -> Obese | AJ18: 94 | AK18: 8480-6 | AL18: 8462-4 | AM18: 8867-4 | AN18: 39156-5 | AO18: 59408-5
A19: PID-0008 | B19: ENC-0008-01 | C19: 45609 | D19: Outpatient | E19: Eastside Clinic | F19: Thika | G19: Dr. T. Osei | H19: 19055 | I19: 73 | J19: {=_xlfn.IFS(EHR[[#This Row],[Age_at_Encounter]]<18,"Adolescent",AND(EHR[[#This Row],[Age_at_Encounter]]>=18,EHR[[#This Row],[Age_at_Encounter]]<=34),"Young Adults",AND(EHR[[#This Row],[Age_at_Encounter]]>=35,EHR[[#This Row],[Age_at_Encounter]]<=49),"Middle Age",AND(EHR[[#This Row],[Age_at_Encounter]]>=50,EHR[[#This Row],[Age_at_Encounter]]<=64),"Late middle Age",EHR[[#This Row],[Age_at_Encounter]]>=65,"Senior Adults")} -> Senior Adults | K19: Male | L19: Middle Eastern | M19: None | N19: Current | O19: Occasional | P19: LD27 | Q19: =_xlfn.XLOOKUP(EHR[[#This Row],[Primary_ICD11_Code]],'03_ICD11_Reference'!A:A,'03_ICD11_Reference'!D:D,,0) -> Genitourinary | R19: Urinary tract infection | S19: No | T19: Furosemide 40mg OD; Ramipril 5mg OD | U19: 2 | V19: =_xlfn.XLOOKUP(EHR[[#This Row],[Encounter_ID]],'02_Lab_Results'!B:B,'02_Lab_Results'!D:D,,0) -> 13457-7 | W19: =_xlfn.XLOOKUP(EHR[[#This Row],[LOINC Code]],'04_LOINC_Reference'!A:A,'04_LOINC_Reference'!F:F,,0) -> Biochemistry | X19: =_xlfn.XLOOKUP(EHR[[#This Row],[LOINC Code]],'02_Lab_Results'!D:D,'02_Lab_Results'!E:E,,0) -> LDL cholesterol | Y19: =_xlfn.XLOOKUP(EHR[[#This Row],[LOINC Code]],'02_Lab_Results'!D:D,'02_Lab_Results'!J:J,,0) -> High | Z19: {=_xlfn.XLOOKUP(1,(B19=B$2:B$500)*(V$2:V$500="4548-4"),Y$2:Y$500,"Not Tested")} -> Not Tested | AA19: 104 | AB19: 102 | AC19: =IF(AND(EHR[[#This Row],[BP_Systolic_mmHg]]<140,EHR[[#This Row],[BP_Diastolic_mmHg]]<90),"Controlled",IF(OR(EHR[[#This Row],[BP_Systolic_mmHg]]="Not Recorded",EHR[[#This Row],[BP_Diastolic_mmHg]]="Not Recorded"),"No Reading","Uncontrolled")) -> Uncontrolled | AD19: =_xlfn.CONCAT(EHR[[#This Row],[BP_Systolic_mmHg]],"/",EHR[[#This Row],[BP_Diastolic_mmHg]]) -> 104/102 | AE19: 116 | AF19: 19 | AG19: 38 | AH19: 21.9 | AI19: =IF(EHR[[#This Row],[BMI_kg_m2]]>=30,"Obese","Non-Obese") -> Non-Obese | AJ19: 99 | AK19: 8480-6 | AL19: 8462-4 | AM19: 8867-4 | AN19: 39156-5 | AO19: 59408-5
A20: PID-0008 | B20: ENC-0008-02 | C20: 45612 | D20: Inpatient | E20: Metro Emergency Unit | F20: Nakuru | G20: Dr. R. Mendes | H20: 19055 | I20: 73 | J20: {=_xlfn.IFS(EHR[[#This Row],[Age_at_Encounter]]<18,"Adolescent",AND(EHR[[#This Row],[Age_at_Encounter]]>=18,EHR[[#This Row],[Age_at_Encounter]]<=34),"Young Adults",AND(EHR[[#This Row],[Age_at_Encounter]]>=35,EHR[[#This Row],[Age_at_Encounter]]<=49),"Middle Age",AND(EHR[[#This Row],[Age_at_Encounter]]>=50,EHR[[#This Row],[Age_at_Encounter]]<=64),"Late middle Age",EHR[[#This Row],[Age_at_Encounter]]>=65,"Senior Adults")} -> Senior Adults | K20: Male | L20: Black African | M20: None | N20: Current | O20: Occasional | P20: LD27 | Q20: =_xlfn.XLOOKUP(EHR[[#This Row],[Primary_ICD11_Code]],'03_ICD11_Reference'!A:A,'03_ICD11_Reference'!D:D,,0) -> Genitourinary | R20: Urinary tract infection | S20: No | T20: Warfarin (variable); Metoprolol 50mg BD | U20: 2 | V20: =_xlfn.XLOOKUP(EHR[[#This Row],[Encounter_ID]],'02_Lab_Results'!B:B,'02_Lab_Results'!D:D,,0) -> 2160-0 | W20: =_xlfn.XLOOKUP(EHR[[#This Row],[LOINC Code]],'04_LOINC_Reference'!A:A,'04_LOINC_Reference'!F:F,,0) -> Biochemistry | X20: =_xlfn.XLOOKUP(EHR[[#This Row],[LOINC Code]],'02_Lab_Results'!D:D,'02_Lab_Results'!E:E,,0) -> Serum creatinine | Y20: =_xlfn.XLOOKUP(EHR[[#This Row],[LOINC Code]],'02_Lab_Results'!D:D,'02_Lab_Results'!J:J,,0) -> Normal | Z20: {=_xlfn.XLOOKUP(1,(B20=B$2:B$500)*(V$2:V$500="4548-4"),Y$2:Y$500,"Not Tested")} -> Not Tested | AA20: 173 | AB20: 104 | AC20: =IF(AND(EHR[[#This Row],[BP_Systolic_mmHg]]<140,EHR[[#This Row],[BP_Diastolic_mmHg]]<90),"Controlled",IF(OR(EHR[[#This Row],[BP_Systolic_mmHg]]="Not Recorded",EHR[[#This Row],[BP_Diastolic_mmHg]]="Not Recorded"),"No Reading","Uncontrolled")) -> Uncontrolled | AD20: =_xlfn.CONCAT(EHR[[#This Row],[BP_Systolic_mmHg]],"/",EHR[[#This Row],[BP_Diastolic_mmHg]]) -> 173/104 | AE20: 70 | AF20: 25 | AG20: 36.3 | AH20: 42.4 | AI20: =IF(EHR[[#This Row],[BMI_kg_m2]]>=30,"Obese","Non-Obese") -> Obese | AJ20: 98 | AK20: 8480-6 | AL20: 8462-4 | AM20: 8867-4 | AN20: 39156-5 | AO20: 59408-5
A21: PID-0009 | B21: ENC-0009-01 | C21: 45045 | D21: Telehealth | E21: Riverside Specialist Centre | F21: Nakuru | G21: Dr. Y. Kim | H21: 20615 | I21: 69 | J21: {=_xlfn.IFS(EHR[[#This Row],[Age_at_Encounter]]<18,"Adolescent",AND(EHR[[#This Row],[Age_at_Encounter]]>=18,EHR[[#This Row],[Age_at_Encounter]]<=34),"Young Adults",AND(EHR[[#This Row],[Age_at_Encounter]]>=35,EHR[[#This Row],[Age_at_Encounter]]<=49),"Middle Age",AND(EHR[[#This Row],[Age_at_Encounter]]>=50,EHR[[#This Row],[Age_at_Encounter]]<=64),"Late middle Age",EHR[[#This Row],[Age_at_Encounter]]>=65,"Senior Adults")} -> Senior Adults | K21: Male | L21: Black African | M21: Private | N21: Unknown | O21: Regular | P21: CA80 | Q21: =_xlfn.XLOOKUP(EHR[[#This Row],[Primary_ICD11_Code]],'03_ICD11_Reference'!A:A,'03_ICD11_Reference'!D:D,,0) -> Respiratory | R21: Asthma | S21: Yes | T21: Ramipril 5mg OD; Empagliflozin 10mg OD; Atorvastatin 40mg ON | U21: 3 | V21: =_xlfn.XLOOKUP(EHR[[#This Row],[Encounter_ID]],'02_Lab_Results'!B:B,'02_Lab_Results'!D:D,,0) -> 2093-3 | W21: =_xlfn.XLOOKUP(EHR[[#This Row],[LOINC Code]],'04_LOINC_Reference'!A:A,'04_LOINC_Reference'!F:F,,0) -> Biochemistry | X21: =_xlfn.XLOOKUP(EHR[[#This Row],[LOINC Code]],'02_Lab_Results'!D:D,'02_Lab_Results'!E:E,,0) -> Total cholesterol | Y21: =_xlfn.XLOOKUP(EHR[[#This Row],[LOINC Code]],'02_Lab_Results'!D:D,'02_Lab_Results'!J:J,,0) -> Normal | Z21: {=_xlfn.XLOOKUP(1,(B21=B$2:B$500)*(V$2:V$500="4548-4"),Y$2:Y$500,"Not Tested")} -> Not Tested | AA21: 174 | AB21: 71 | AC21: =IF(AND(EHR[[#This Row],[BP_Systolic_mmHg]]<140,EHR[[#This Row],[BP_Diastolic_mmHg]]<90),"Controlled",IF(OR(EHR[[#This Row],[BP_Systolic_mmHg]]="Not Recorded",EHR[[#This Row],[BP_Diastolic_mmHg]]="Not Recorded"),"No Reading","Uncontrolled")) -> Uncontrolled | AD21: =_xlfn.CONCAT(EHR[[#This Row],[BP_Systolic_mmHg]],"/",EHR[[#This Row],[BP_Diastolic_mmHg]]) -> 174/71 | AE21: 94 | AF21: 28 | AG21: 36.1 | AH21: 34.5 | AI21: =IF(EHR[[#This Row],[BMI_kg_m2]]>=30,"Obese","Non-Obese") -> Obese | AJ21: 91 | AK21: 8480-6 | AL21: 8462-4 | AM21: 8867-4 | AN21: 39156-5 | AO21: 59408-5
A22: PID-0009 | B22: ENC-0009-02 | C22: 45652 | D22: Inpatient | E22: Riverside Specialist Centre | F22: Eldoret | G22: Dr. T. Osei | H22: 20615 | I22: 69 | J22: {=_xlfn.IFS(EHR[[#This Row],[Age_at_Encounter]]<18,"Adolescent",AND(EHR[[#This Row],[Age_at_Encounter]]>=18,EHR[[#This Row],[Age_at_Encounter]]<=34),"Young Adults",AND(EHR[[#This Row],[Age_at_Encounter]]>=35,EHR[[#This Row],[Age_at_Encounter]]<=49),"Middle Age",AND(EHR[[#This Row],[Age_at_Encounter]]>=50,EHR[[#This Row],[Age_at_Encounter]]<=64),"Late middle Age",EHR[[#This Row],[Age_at_Encounter]]>=65,"Senior Adults")} -> Senior Adults | K22: Male | L22: South Asian | M22: Private | N22: Unknown | O22: Regular | P22: CA80 | Q22: =_xlfn.XLOOKUP(EHR[[#This Row],[Primary_ICD11_Code]],'03_ICD11_Reference'!A:A,'03_ICD11_Reference'!D:D,,0) -> Respiratory | R22: Asthma | S22: Yes | T22: Metformin 1g BD; Levothyroxine 50mcg OD; Clopidogrel 75mg OD; Atorvastatin 40mg ON | U22: 4 | V22: =_xlfn.XLOOKUP(EHR[[#This Row],[Encounter_ID]],'02_Lab_Results'!B:B,'02_Lab_Results'!D:D,,0) -> 2951-2 | W22: =_xlfn.XLOOKUP(EHR[[#This Row],[LOINC Code]],'04_LOINC_Reference'!A:A,'04_LOINC_Reference'!F:F,,0) -> Biochemistry | X22: =_xlfn.XLOOKUP(EHR[[#This Row],[LOINC Code]],'02_Lab_Results'!D:D,'02_Lab_Results'!E:E,,0) -> Serum sodium | Y22: =_xlfn.XLOOKUP(EHR[[#This Row],[LOINC Code]],'02_Lab_Results'!D:D,'02_Lab_Results'!J:J,,0) -> Low | Z22: {=_xlfn.XLOOKUP(1,(B22=B$2:B$500)*(V$2:V$500="4548-4"),Y$2:Y$500,"Not Tested")} -> Not Tested | AA22: 134 | AB22: 86 | AC22: =IF(AND(EHR[[#This Row],[BP_Systolic_mmHg]]<140,EHR[[#This Row],[BP_Diastolic_mmHg]]<90),"Controlled",IF(OR(EHR[[#This Row],[BP_Systolic_mmHg]]="Not Recorded",EHR[[#This Row],[BP_Diastolic_mmHg]]="Not Recorded"),"No Reading","Uncontrolled")) -> Controlled | AD22: =_xlfn.CONCAT(EHR[[#This Row],[BP_Systolic_mmHg]],"/",EHR[[#This Row],[BP_Diastolic_mmHg]]) -> 134/86 | AE22: 110 | AF22: 23 | AG22: 39 | AH22: 38.5 | AI22: =IF(EHR[[#This Row],[BMI_kg_m2]]>=30,"Obese","Non-Obese") -> Obese | AJ22: 90 | AK22: 8480-6 | AL22: 8462-4 | AM22: 8867-4 | AN22: 39156-5 | AO22: 59408-5
A23: PID-0009 | B23: ENC-0009-03 | C23: 45339 | D23: Inpatient | E23: Metro Emergency Unit | F23: Nakuru | G23: Dr. T. Osei | H23: 20615 | I23: 69 | J23: {=_xlfn.IFS(EHR[[#This Row],[Age_at_Encounter]]<18,"Adolescent",AND(EHR[[#This Row],[Age_at_Encounter]]>=18,EHR[[#This Row],[Age_at_Encounter]]<=34),"Young Adults",AND(EHR[[#This Row],[Age_at_Encounter]]>=35,EHR[[#This Row],[Age_at_Encounter]]<=49),"Middle Age",AND(EHR[[#This Row],[Age_at_Encounter]]>=50,EHR[[#This Row],[Age_at_Encounter]]<=64),"Late middle Age",EHR[[#This Row],[Age_at_Encounter]]>=65,"Senior Adults")} -> Senior Adults | K23: Male | L23: Middle Eastern | M23: Private | N23: Unknown | O23: Regular | P23: CA80 | Q23: =_xlfn.XLOOKUP(EHR[[#This Row],[Primary_ICD11_Code]],'03_ICD11_Reference'!A:A,'03_ICD11_Reference'!D:D,,0) -> Respiratory | R23: Asthma | S23: Yes | T23: Amlodipine 10mg OD; Prednisolone 5mg OD; Amlodipine 5mg OD | U23: 3 | V23: =_xlfn.XLOOKUP(EHR[[#This Row],[Encounter_ID]],'02_Lab_Results'!B:B,'02_Lab_Results'!D:D,,0) -> 789-8 | W23: =_xlfn.XLOOKUP(EHR[[#This Row],[LOINC Code]],'04_LOINC_Reference'!A:A,'04_LOINC_Reference'!F:F,,0) -> Biochemistry | X23: =_xlfn.XLOOKUP(EHR[[#This Row],[LOINC Code]],'02_Lab_Results'!D:D,'02_Lab_Results'!E:E,,0) -> RBC count | Y23: =_xlfn.XLOOKUP(EHR[[#This Row],[LOINC Code]],'02_Lab_Results'!D:D,'02_Lab_Results'!J:J,,0) -> High | Z23: {=_xlfn.XLOOKUP(1,(B23=B$2:B$500)*(V$2:V$500="4548-4"),Y$2:Y$500,"Not Tested")} -> Not Tested | AA23: 158 | AB23: 88 | AC23: =IF(AND(EHR[[#This Row],[BP_Systolic_mmHg]]<140,EHR[[#This Row],[BP_Diastolic_mmHg]]<90),"Controlled",IF(OR(EHR[[#This Row],[BP_Systolic_mmHg]]="Not Recorded",EHR[[#This Row],[BP_Diastolic_mmHg]]="Not Recorded"),"No Reading","Uncontrolled")) -> Uncontrolled | AD23: =_xlfn.CONCAT(EHR[[#This Row],[BP_Systolic_mmHg]],"/",EHR[[#This Row],[BP_Diastolic_mmHg]]) -> 158/88 | AE23: 64 | AF23: 23 | AG23: 37.2 | AH23: 38.8 | AI23: =IF(EHR[[#This Row],[BMI_kg_m2]]>=30,"Obese","Non-Obese") -> Obese | AJ23: 89 | AK23: 8480-6 | AL23: 8462-4 | AM23: 8867-4 | AN23: 39156-5 | AO23: 59408-5
A24: PID-0010 | B24: ENC-0010-01 | C24: 45606 | D24: Emergency | E24: Community Health Centre | F24: Kitale | G24: Dr. S. Okonkwo | H24: 17760 | I24: 77 | J24: {=_xlfn.IFS(EHR[[#This Row],[Age_at_Encounter]]<18,"Adolescent",AND(EHR[[#This Row],[Age_at_Encounter]]>=18,EHR[[#This Row],[Age_at_Encounter]]<=34),"Young Adults",AND(EHR[[#This Row],[Age_at_Encounter]]>=35,EHR[[#This Row],[Age_at_Encounter]]<=49),"Middle Age",AND(EHR[[#This Row],[Age_at_Encounter]]>=50,EHR[[#This Row],[Age_at_Encounter]]<=64),"Late middle Age",EHR[[#This Row],[Age_at_Encounter]]>=65,"Senior Adults")} -> Senior Adults | K24: Female | L24: East Asian | M24: Employer | N24: Ex-smoker | O24: None | P24: 8A00 | Q24: =_xlfn.XLOOKUP(EHR[[#This Row],[Primary_ICD11_Code]],'03_ICD11_Reference'!A:A,'03_ICD11_Reference'!D:D,,0) -> Neurological | R24: Ischaemic stroke | S24: No | T24: Lisinopril 10mg OD | U24: 1 | V24: =_xlfn.XLOOKUP(EHR[[#This Row],[Encounter_ID]],'02_Lab_Results'!B:B,'02_Lab_Results'!D:D,,0) -> 2777-1 | W24: =_xlfn.XLOOKUP(EHR[[#This Row],[LOINC Code]],'04_LOINC_Reference'!A:A,'04_LOINC_Reference'!F:F,,0) -> Biochemistry | X24: =_xlfn.XLOOKUP(EHR[[#This Row],[LOINC Code]],'02_Lab_Results'!D:D,'02_Lab_Results'!E:E,,0) -> Serum phosphate | Y24: =_xlfn.XLOOKUP(EHR[[#This Row],[LOINC Code]],'02_Lab_Results'!D:D,'02_Lab_Results'!J:J,,0) -> Normal | Z24: {=_xlfn.XLOOKUP(1,(B24=B$2:B$500)*(V$2:V$500="4548-4"),Y$2:Y$500,"Not Tested")} -> Not Tested | AA24: 152 | AB24: 75 | AC24: =IF(AND(EHR[[#This Row],[BP_Systolic_mmHg]]<140,EHR[[#This Row],[BP_Diastolic_mmHg]]<90),"Controlled",IF(OR(EHR[[#This Row],[BP_Systolic_mmHg]]="Not Recorded",EHR[[#This Row],[BP_Diastolic_mmHg]]="Not Recorded"),"No Reading","Uncontrolled")) -> Uncontrolled | AD24: =_xlfn.CONCAT(EHR[[#This Row],[BP_Systolic_mmHg]],"/",EHR[[#This Row],[BP_Diastolic_mmHg]]) -> 152/75 | AE24: 111 | AF24: 24 | AG24: 38.2 | AH24: 23.9 | AI24: =IF(EHR[[#This Row],[BMI_kg_m2]]>=30,"Obese","Non-Obese") -> Non-Obese | AJ24: 90 | AK24: 8480-6 | AL24: 8462-4 | AM24: 8867-4 | AN24: 39156-5 | AO24: 59408-5
A25: PID-0010 | B25: ENC-0010-02 | C25: 45351 | D25: Emergency | E25: Eastside Clinic | F25: Garissa | G25: NP J. Nakamura | H25: 17760 | I25: 77 | J25: {=_xlfn.IFS(EHR[[#This Row],[Age_at_Encounter]]<18,"Adolescent",AND(EHR[[#This Row],[Age_at_Encounter]]>=18,EHR[[#This Row],[Age_at_Encounter]]<=34),"Young Adults",AND(EHR[[#This Row],[Age_at_Encounter]]>=35,EHR[[#This Row],[Age_at_Encounter]]<=49),"Middle Age",AND(EHR[[#This Row],[Age_at_Encounter]]>=50,EHR[[#This Row],[Age_at_Encounter]]<=64),"Late middle Age",EHR[[#This Row],[Age_at_Encounter]]>=65,"Senior Adults")} -> Senior Adults | K25: Female | L25: Black African | M25: Employer | N25: Ex-smoker | O25: None | P25: 8A00 | Q25: =_xlfn.XLOOKUP(EHR[[#This Row],[Primary_ICD11_Code]],'03_ICD11_Reference'!A:A,'03_ICD11_Reference'!D:D,,0) -> Neurological | R25: Ischaemic stroke | S25: No | T25: Ramipril 5mg OD | U25: 1 | V25: =_xlfn.XLOOKUP(EHR[[#This Row],[Encounter_ID]],'02_Lab_Results'!B:B,'02_Lab_Results'!D:D,,0) -> 13457-7 | W25: =_xlfn.XLOOKUP(EHR[[#This Row],[LOINC Code]],'04_LOINC_Reference'!A:A,'04_LOINC_Reference'!F:F,,0) -> Biochemistry | X25: =_xlfn.XLOOKUP(EHR[[#This Row],[LOINC Code]],'02_Lab_Results'!D:D,'02_Lab_Results'!E:E,,0) -> LDL cholesterol | Y25: =_xlfn.XLOOKUP(EHR[[#This Row],[LOINC Code]],'02_Lab_Results'!D:D,'02_Lab_Results'!J:J,,0) -> High | Z25: {=_xlfn.XLOOKUP(1,(B25=B$2:B$500)*(V$2:V$500="4548-4"),Y$2:Y$500,"Not Tested")} -> Not Tested | AA25: 175 | AB25: 90 | AC25: =IF(AND(EHR[[#This Row],[BP_Systolic_mmHg]]<140,EHR[[#This Row],[BP_Diastolic_mmHg]]<90),"Controlled",IF(OR(EHR[[#This Row],[BP_Systolic_mmHg]]="Not Recorded",EHR[[#This Row],[BP_Diastolic_mmHg]]="Not Recorded"),"No Reading","Uncontrolled")) -> Uncontrolled | AD25: =_xlfn.CONCAT(EHR[[#This Row],[BP_Systolic_mmHg]],"/",EHR[[#This Row],[BP_Diastolic_mmHg]]) -> 175/90 | AE25: 104 | AF25: 18 | AG25: 37.3 | AH25: 21.7 | AI25: =IF(EHR[[#This Row],[BMI_kg_m2]]>=30,"Obese","Non-Obese") -> Non-Obese | AJ25: 96 | AK25: 8480-6 | AL25: 8462-4 | AM25: 8867-4 | AN25: 39156-5 | AO25: 59408-5
... A50: PID-0016 | B50: ENC-0016-02 | C50: 45662 | D50: Outpatient | E50: Central District Hospital | F50: Nyeri | G50: Dr. L. Patel | H50: 21753 | I50: 66 | J50: {=_xlfn.IFS(EHR[[#This Row],[Age_at_Encounter]]<18,"Adolescent",AND(EHR[[#This Row],[Age_at_Encounter]]>=18,EHR[[#This Row],[Age_at_Encounter]]<=34),"Young Adults",AND(EHR[[#This Row],[Age_at_Encounter]]>=35,EHR[[#This Row],[Age_at_Encounter]]<=49),"Middle Age",AND(EHR[[#This Row],[Age_at_Encounter]]>=50,EHR[[#This Row],[Age_at_Encounter]]<=64),"Late middle Age",EHR[[#This Row],[Age_at_Encounter]]>=65,"Senior Adults")} -> Senior Adults | K50: Female | L50: Hispanic/Latino | M50: None | N50: Ex-smoker | O50: Regular | P50: JA00 | Q50: =_xlfn.XLOOKUP(EHR[[#This Row],[Primary_ICD11_Code]],'03_ICD11_Reference'!A:A,'03_ICD11_Reference'!D:D,,0) -> Infectious | R50: Community-acquired pneumonia | S50: No | T50: Metformin 1g BD; Ramipril 5mg OD | U50: 2 | V50: =_xlfn.XLOOKUP(EHR[[#This Row],[Encounter_ID]],'02_Lab_Results'!B:B,'02_Lab_Results'!D:D,,0) -> 2093-3 | W50: =_xlfn.XLOOKUP(EHR[[#This Row],[LOINC Code]],'04_LOINC_Reference'!A:A,'04_LOINC_Reference'!F:F,,0) -> Biochemistry | X50: =_xlfn.XLOOKUP(EHR[[#This Row],[LOINC Code]],'02_Lab_Results'!D:D,'02_Lab_Results'!E:E,,0) -> Total cholesterol | Y50: =_xlfn.XLOOKUP(EHR[[#This Row],[LOINC Code]],'02_Lab_Results'!D:D,'02_Lab_Results'!J:J,,0) -> Normal | Z50: {=_xlfn.XLOOKUP(1,(B50=B$2:B$500)*(V$2:V$500="4548-4"),Y$2:Y$500,"Not Tested")} -> Not Tested | AA50: 175 | AB50: 84 | AC50: =IF(AND(EHR[[#This Row],[BP_Systolic_mmHg]]<140,EHR[[#This Row],[BP_Diastolic_mmHg]]<90),"Controlled",IF(OR(EHR[[#This Row],[BP_Systolic_mmHg]]="Not Recorded",EHR[[#This Row],[BP_Diastolic_mmHg]]="Not Recorded"),"No Reading","Uncontrolled")) -> Uncontrolled | AD50: =_xlfn.CONCAT(EHR[[#This Row],[BP_Systolic_mmHg]],"/",EHR[[#This Row],[BP_Diastolic_mmHg]]) -> 175/84 | AE50: 91 | AF50: 22 | AG50: 36.8 | AH50: 37 | AI50: =IF(EHR[[#This Row],[BMI_kg_m2]]>=30,"Obese","Non-Obese") -> Obese | AJ50: 91 | AK50: 8480-6 | AL50: 8462-4 | AM50: 8867-4 | AN50: 39156-5 | AO50: 59408-5
A51: PID-0017 | B51: ENC-0017-01 | C51: =EHR[[#This Row],[Patient_DOB]]+(EHR[[#This Row],[Age_at_Encounter]]*365) -> 45662 | D51: Inpatient | E51: Community Health Centre | F51: Eldoret | G51: Dr. A. Mwangi | H51: 37997 | I51: 21 | J51: {=_xlfn.IFS(EHR[[#This Row],[Age_at_Encounter]]<18,"Adolescent",AND(EHR[[#This Row],[Age_at_Encounter]]>=18,EHR[[#This Row],[Age_at_Encounter]]<=34),"Young Adults",AND(EHR[[#This Row],[Age_at_Encounter]]>=35,EHR[[#This Row],[Age_at_Encounter]]<=49),"Middle Age",AND(EHR[[#This Row],[Age_at_Encounter]]>=50,EHR[[#This Row],[Age_at_Encounter]]<=64),"Late middle Age",EHR[[#This Row],[Age_at_Encounter]]>=65,"Senior Adults")} -> Young Adults | K51: Female | L51: Middle Eastern | M51: Private | N51: Current | O51: Unknown | P51: 5A11 | Q51: =_xlfn.XLOOKUP(EHR[[#This Row],[Primary_ICD11_Code]],'03_ICD11_Reference'!A:A,'03_ICD11_Reference'!D:D,,0) -> Endocrine | R51: Type 2 diabetes mellitus | S51: Yes | T51: Clopidogrel 75mg OD; Salbutamol 100mcg PRN; Aspirin 75mg OD; Metoprolol 50mg BD | U51: 4 | V51: =_xlfn.XLOOKUP(EHR[[#This Row],[Encounter_ID]],'02_Lab_Results'!B:B,'02_Lab_Results'!D:D,,0) -> 6690-2 | W51: =_xlfn.XLOOKUP(EHR[[#This Row],[LOINC Code]],'04_LOINC_Reference'!A:A,'04_LOINC_Reference'!F:F,,0) -> Biochemistry | X51: =_xlfn.XLOOKUP(EHR[[#This Row],[LOINC Code]],'02_Lab_Results'!D:D,'02_Lab_Results'!E:E,,0) -> WBC count | Y51: =_xlfn.XLOOKUP(EHR[[#This Row],[LOINC Code]],'02_Lab_Results'!D:D,'02_Lab_Results'!J:J,,0) -> Low | Z51: {=_xlfn.XLOOKUP(1,(B51=B$2:B$500)*(V$2:V$500="4548-4"),Y$2:Y$500,"Not Tested")} -> Not Tested | AA51: 132 | AB51: Not Recorded | AC51: =IF(AND(EHR[[#This Row],[BP_Systolic_mmHg]]<140,EHR[[#This Row],[BP_Diastolic_mmHg]]<90),"Controlled",IF(OR(EHR[[#This Row],[BP_Systolic_mmHg]]="Not Recorded",EHR[[#This Row],[BP_Diastolic_mmHg]]="Not Recorded"),"No Reading","Uncontrolled")) -> No Reading | AD51: =_xlfn.CONCAT(EHR[[#This Row],[BP_Systolic_mmHg]],"/",EHR[[#This Row],[BP_Diastolic_mmHg]]) -> 132/Not Recorded | AE51: 64 | AF51: 15 | AG51: 38 | AH51: 28.4 | AI51: =IF(EHR[[#This Row],[BMI_kg_m2]]>=30,"Obese","Non-Obese") -> Non-Obese | AJ51: 96 | AK51: 8480-6 | AL51: 8462-4 | AM51: 8867-4 | AN51: 39156-5 | AO51: 59408-5
A52: PID-0017 | B52: ENC-0017-02 | C52: =EHR[[#This Row],[Patient_DOB]]+(EHR[[#This Row],[Age_at_Encounter]]*365) -> 45662 | D52: Telehealth | E52: Riverside Specialist Centre | F52: Thika | G52: Dr. Y. Kim | H52: 37997 | I52: 21 | J52: {=_xlfn.IFS(EHR[[#This Row],[Age_at_Encounter]]<18,"Adolescent",AND(EHR[[#This Row],[Age_at_Encounter]]>=18,EHR[[#This Row],[Age_at_Encounter]]<=34),"Young Adults",AND(EHR[[#This Row],[Age_at_Encounter]]>=35,EHR[[#This Row],[Age_at_Encounter]]<=49),"Middle Age",AND(EHR[[#This Row],[Age_at_Encounter]]>=50,EHR[[#This Row],[Age_at_Encounter]]<=64),"Late middle Age",EHR[[#This Row],[Age_at_Encounter]]>=65,"Senior Adults")} -> Young Adults | K52: Female | L52: Hispanic/Latino | M52: Private | N52: Current | O52: Unknown | P52: 5A11 | Q52: =_xlfn.XLOOKUP(EHR[[#This Row],[Primary_ICD11_Code]],'03_ICD11_Reference'!A:A,'03_ICD11_Reference'!D:D,,0) -> Endocrine | R52: Type 2 diabetes mellitus | S52: Yes | T52: Aspirin 75mg OD | U52: 1 | V52: =_xlfn.XLOOKUP(EHR[[#This Row],[Encounter_ID]],'02_Lab_Results'!B:B,'02_Lab_Results'!D:D,,0) -> 2093-3 | W52: =_xlfn.XLOOKUP(EHR[[#This Row],[LOINC Code]],'04_LOINC_Reference'!A:A,'04_LOINC_Reference'!F:F,,0) -> Biochemistry | X52: =_xlfn.XLOOKUP(EHR[[#This Row],[LOINC Code]],'02_Lab_Results'!D:D,'02_Lab_Results'!E:E,,0) -> Total cholesterol | Y52: =_xlfn.XLOOKUP(EHR[[#This Row],[LOINC Code]],'02_Lab_Results'!D:D,'02_Lab_Results'!J:J,,0) -> Normal | Z52: {=_xlfn.XLOOKUP(1,(B52=B$2:B$500)*(V$2:V$500="4548-4"),Y$2:Y$500,"Not Tested")} -> Not Tested | AA52: Not Recorded | AB52: 113 | AC52: =IF(AND(EHR[[#This Row],[BP_Systolic_mmHg]]<140,EHR[[#This Row],[BP_Diastolic_mmHg]]<90),"Controlled",IF(OR(EHR[[#This Row],[BP_Systolic_mmHg]]="Not Recorded",EHR[[#This Row],[BP_Diastolic_mmHg]]="Not Recorded"),"No Reading","Uncontrolled")) -> No Reading | AD52: =_xlfn.CONCAT(EHR[[#This Row],[BP_Systolic_mmHg]],"/",EHR[[#This Row],[BP_Diastolic_mmHg]]) -> Not Recorded/113 | AE52: 102 | AF52: 19 | AG52: 37 | AH52: 46 | AI52: =IF(EHR[[#This Row],[BMI_kg_m2]]>=30,"Obese","Non-Obese") -> Obese | AJ52: 98 | AK52: 8480-6 | AL52: 8462-4 | AM52: 8867-4 | AN52: 39156-5 | AO52: 59408-5
A53: PID-0017 | B53: ENC-0017-03 | C53: =EHR[[#This Row],[Patient_DOB]]+(EHR[[#This Row],[Age_at_Encounter]]*365) -> 45662 | D53: Emergency | E53: Eastside Clinic | F53: Kitale | G53: Dr. Y. Kim | H53: 37997 | I53: 21 | J53: {=_xlfn.IFS(EHR[[#This Row],[Age_at_Encounter]]<18,"Adolescent",AND(EHR[[#This Row],[Age_at_Encounter]]>=18,EHR[[#This Row],[Age_at_Encounter]]<=34),"Young Adults",AND(EHR[[#This Row],[Age_at_Encounter]]>=35,EHR[[#This Row],[Age_at_Encounter]]<=49),"Middle Age",AND(EHR[[#This Row],[Age_at_Encounter]]>=50,EHR[[#This Row],[Age_at_Encounter]]<=64),"Late middle Age",EHR[[#This Row],[Age_at_Encounter]]>=65,"Senior Adults")} -> Young Adults | K53: Female | L53: Hispanic/Latino | M53: Private | N53: Current | O53: Unknown | P53: 5A11 | Q53: =_xlfn.XLOOKUP(EHR[[#This Row],[Primary_ICD11_Code]],'03_ICD11_Reference'!A:A,'03_ICD11_Reference'!D:D,,0) -> Endocrine | R53: Type 2 diabetes mellitus | S53: Yes | T53: None; Insulin glargine 20u ON | U53: 2 | V53: =_xlfn.XLOOKUP(EHR[[#This Row],[Encounter_ID]],'02_Lab_Results'!B:B,'02_Lab_Results'!D:D,,0) -> 2823-3 | W53: =_xlfn.XLOOKUP(EHR[[#This Row],[LOINC Code]],'04_LOINC_Reference'!A:A,'04_LOINC_Reference'!F:F,,0) -> Biochemistry | X53: =_xlfn.XLOOKUP(EHR[[#This Row],[LOINC Code]],'02_Lab_Results'!D:D,'02_Lab_Results'!E:E,,0) -> Serum potassium | Y53: =_xlfn.XLOOKUP(EHR[[#This Row],[LOINC Code]],'02_Lab_Results'!D:D,'02_Lab_Results'!J:J,,0) -> Normal | Z53: {=_xlfn.XLOOKUP(1,(B53=B$2:B$500)*(V$2:V$500="4548-4"),Y$2:Y$500,"Not Tested")} -> Not Tested | AA53: 165 | AB53: 113 | AC53: =IF(AND(EHR[[#This Row],[BP_Systolic_mmHg]]<140,EHR[[#This Row],[BP_Diastolic_mmHg]]<90),"Controlled",IF(OR(EHR[[#This Row],[BP_Systolic_mmHg]]="Not Recorded",EHR[[#This Row],[BP_Diastolic_mmHg]]="Not Recorded"),"No Reading","Uncontrolled")) -> Uncontrolled | AD53: =_xlfn.CONCAT(EHR[[#This Row],[BP_Systolic_mmHg]],"/",EHR[[#This Row],[BP_Diastolic_mmHg]]) -> 165/113 | AE53: 118 | AF53: 24 | AG53: 38.7 | AH53: Invalid | AI53: =IF(EHR[[#This Row],[BMI_kg_m2]]>=30,"Obese","Non-Obese") -> Obese | AJ53: 97 | AK53: 8480-6 | AL53: 8462-4 | AM53: 8867-4 | AN53: 39156-5 | AO53: 59408-5
